Workbook

Sheet Sheet1
A1: bijdragen en uitgaven per capita | C1: 1. aandeel bijdragen versus uitgaven
A2: equivalentie uitgaven en bijdragen | C2: 2. evolutie aangeslotenen, bijdragen en uitgaven | G2: probleem zit bij de uitgaven
A5: Aangeslotenen
A6: (Bron data aangeslotenen: KSZ) | C6: 2003 | D6: 2004 | E6: 2005 | F6: 2006 | G6: 2007 | H6: 2008 | I6: 2009 | J6: 2010 | K6: 2011 | L6: 2012 | M6: 2013 | N6: 2014 | O6: 2015 | P6: 2016 | Q6: 2017 | R6: 2018 | S6: 2019 | T6: 2020 | U6: 2021 | V6: 2022 | W6: 2023 | X6: 2024
A7: Totaal zelfstandigen (= n12) | C7: 607586 | D7: 610856 | E7: 619161 | F7: 628879 | G7: 644711 | H7: 658933 | I7: 671678 | J7: 684305 | K7: 696052 | L7: 710144 | M7: 719354 | N7: 730291 | O7: 746190 | P7: 762006 | Q7: 781334 | R7: 797011 | S7: 817839 | T7: 845105 | U7: 874522 | V7: 890990 | W7: 881138
A8: % zelfstandigen | C8: =C7/C11 -> 0.14690301 | D8: =D7/D11 -> 0.14668569 | E8: =E7/E11 -> 0.14716112 | F8: =F7/F11 -> 0.14700218 | G8: =G7/G11 -> 0.14749092 | H8: =H7/H11 -> 0.1492558 | I8: =I7/I11 -> 0.15241677 | J8: =J7/J11 -> 0.15314795 | ... W8: =W7/W11 -> 0.17843751
A9: Totaal loontrekkenden (n11) | C9: 3282810 | D9: 3307868 | E9: 3343796 | F9: 3400589 | G9: 3469911 | H9: 3494375 | I9: 3476291 | J9: 3519456 | K9: 3534952 | L9: 3521105 | M9: 3504422 | N9: 3521770 | O9: 3543376 | P9: 3584978 | Q9: 3631146 | R9: 3677621 | S9: 3719648 | T9: 3685781 | U9: 3741208 | V9: 3781366 | W9: 3696753
A10: % loontrekkenden | C10: =C9/C11 -> 0.79372248 | D10: =D9/D11 -> 0.79432291 | E10: =E9/E11 -> 0.79474769 | F10: =F9/F11 -> 0.79489694 | G10: =G9/G11 -> 0.79381363 | H10: =H9/H11 -> 0.79151556 | I10: =I9/I11 -> 0.78883788 | J10: =J9/J11 -> 0.78765676 | ... W10: =W9/W11 -> 0.74862214
A11: Totaal werkenden (= n11, n12, n13, n141, n142, n143) | C11: 4135967 | D11: 4164387 | E11: 4207368 | F11: 4278025 | G11: 4371191 | H11: 4414790 | I11: 4406851 | J11: 4468261 | K11: 4500704 | L11: 4505459 | M11: 4500837 | N11: 4532474 | O11: 4574017 | P11: 4637447 | Q11: 4712713 | R11: 4783951 | S11: 4856922 | T11: 4863008 | U11: 4964745 | V11: 5030500 | W11: 4938076
A12: Noemer RSZ (= Totaal werkenden - totaal zelfstandigen) | C12: =C11-C7 -> 3528381 | D12: =D11-D7 -> 3553531 | E12: =E11-E7 -> 3588207 | F12: =F11-F7 -> 3649146 | G12: =G11-G7 -> 3726480 | H12: =H11-H7 -> 3755857 | I12: =I11-I7 -> 3735173 | J12: =J11-J7 -> 3783956 | ... W12: =W11-W7 -> 4056938
A13: Totaal vennootschappen (Bron: RSVZ) | B13: Aantal | C13: 340404 | D13: 348930 | E13: 354.953 | F13: 373.382 | G13: 387.861 | H13: 413.469 | I13: 429.286 | J13: 445.941 | K13: 464.463 | L13: 477.479 | M13: 484231 | N13: 486.320 | O13: 500.742 | P13: 516.774 | Q13: 533.903 | R13: 551.179 | S13: 565.782 | T13: 597771 | U13: 627.057 | V13: 655.108 | W13: 682936 | X13: 707073
A15: Gepensioneeerden met zelfstandigenpensioen | S15: 638335 | T15: 643230 | U15: 646083 | V15: 654831 | W15: 664545 | X15: 676914
S16: 100 | T16: =(T15/S15)*S16 -> 100.76684 | U16: =(U15/T15)*T16 -> 101.21378 | V16: =(V15/U15)*U16 -> 102.58422 | W16: =(W15/V15)*V16 -> 104.10599 | X16: =(X15/W15)*W16 -> 106.04369
A19: Evolutie zelfstandigen | C19: 100 | D19: =(D7/C7)*C19 -> 100.5382 | E19: =(E7/D7)*D19 -> 101.90508 | F19: =(F7/E7)*E19 -> 103.50452 | G19: =(G7/F7)*F19 -> 106.11025 | H19: =(H7/G7)*G19 -> 108.45098 | I19: =(I7/H7)*H19 -> 110.54863 | J19: =(J7/I7)*I19 -> 112.62685 | K19: =(K7/J7)*J19 -> 114.56024 | ... W19: =(W7/V7)*V19 -> 145.02276
A20: Evolutie loontrekkenden | C20: 100 | D20: =(D9/C9)*C20 -> 100.76331 | E20: =(E9/D9)*D20 -> 101.85774 | F20: =(F9/E9)*E20 -> 103.58775 | G20: =(G9/F9)*F20 -> 105.69942 | H20: =(H9/G9)*G20 -> 106.44463 | I20: =(I9/H9)*H20 -> 105.89376 | J20: =(J9/I9)*I20 -> 107.20864 | K20: =(K9/J9)*J20 -> 107.68068 | ... W20: =(W9/V9)*V20 -> 112.60941
A21: Evolutie vennootschappen | C21: 100 | D21: =(D13/C13)*C21 -> 102.50467 | E21: =(E13/D13)*D21 -> 104.27404 | F21: =(F13/E13)*E21 -> 109.6879 | G21: =(G13/F13)*F21 -> 113.94138 | H21: =(H13/G13)*G21 -> 121.4642 | I21: =(I13/H13)*H21 -> 126.11074 | J21: =(J13/I13)*I21 -> 131.00345 | K21: =(K13/J13)*J21 -> 136.44464 | ... X21: =(X13/W13)*W21 -> 207.71583
A23: Correctie voor inflatie
A24: CPI (2013=100) (bron: Statbel: https://statbel.fgov.be/nl/themas/consumptieprijsindex/consumptieprijsindex#figures --> Excel: Consumptieprijsindex vanaf 1920 en gezondheidsindex vanaf 1994) | C24: 80.03 | D24: 81.71 | E24: 83.98 | F24: 85.48 | G24: 87.04 | H24: 90.95 | I24: 90.9 | J24: 92.89 | K24: 96.17 | L24: 98.9 | M24: 100 | N24: 100.34 | O24: 100.9 | P24: 102.89 | Q24: 105.08 | R24: 107.24 | S24: 108.78 | T24: 109.59 | U24: 112.26 | V24: 123.03 | W24: 128.02
A25: Herwaardering naar factor 2023 ("huidige koopkracht") | C25: =$W24/C24 -> 1.5996501 | D25: =$W24/D24 -> 1.5667605 | E25: =$W24/E24 -> 1.5244106 | F25: =$W24/F24 -> 1.4976603 | G25: =$W24/G24 -> 1.470818 | H25: =$W24/H24 -> 1.4075866 | I25: =$W24/I24 -> 1.4083608 | J25: =$W24/J24 -> 1.3781893 | ... W25: =$W24/W24 -> 1
A26: Bron bedragen zelfstandigen: Excel-file B. Zelfstandigen_2000-2025, verkregen via FOD S.Z.
A27: Bijdragen zelfstandigen
A28: Evolutie bijdragen zelfstandigen | C28: 2362746.5 | D28: 2467975.6 | E28: 2601500.8 | F28: 2737094.7 | G28: 2854576.1 | H28: 3244981.3 | I28: 3415331.3 | J28: 3535058.1 | K28: 3602228.2 | L28: 3746647.9 | M28: 3917483.8 | N28: 3941423.7 | O28: 4194116.6 | P28: 4301696.9 | Q28: 4390940.6 | R28: 4485777.8 | S28: 4567854.7 | T28: 4257700.3 | U28: 4676583.6 | V28: 4843640.9 | W28: 5333723.9 | X28: 5627778.5 | Y28: 5751656.2
C29: 100 | D29: =(D28/C28)*C29 -> 104.45368 | E29: =(E28/D28)*D29 -> 110.10495 | F29: =(F28/E28)*E29 -> 115.84377 | G29: =(G28/F28)*F29 -> 120.81601 | H29: =(H28/G28)*G29 -> 137.33938 | I29: =(I28/H28)*H29 -> 144.54921 | J29: =(J28/I28)*I29 -> 149.61648 | K29: =(K28/J28)*J29 -> 152.45936 | ... W29: =(W28/V28)*V29 -> 225.74254
C30: =C28/C7 -> 3.8887441 | D30: =D28/D7 -> 4.0401921 | E30: =E28/E7 -> 4.2016548 | F30: =F28/F7 -> 4.3523392 | G30: =G28/G7 -> 4.4276832 | H30: =H28/H7 -> 4.9245998 | I30: =I28/I7 -> 5.0847748 | J30: =J28/J7 -> 5.1659101 | ... W30: =W28/W7 -> 6.0532219
A31: Evolutie bijdragen / capita zelfstandigen | C31: 100 | D31: =(D30/C30)*C31 -> 103.89452 | E31: =(E30/D30)*D31 -> 108.04657 | F31: =(F30/E30)*E31 -> 111.92146 | G31: =(G30/F30)*F31 -> 113.85895 | H31: =(H30/G30)*G31 -> 126.63728 | I31: =(I30/H30)*H31 -> 130.75622 | J31: =(J30/I30)*I31 -> 132.84263 | K31: =(K30/J30)*J31 -> 133.08226 | ... W31: =(W30/V30)*V31 -> 155.66007
A32: Evolutie bijdragen zelfstandigen gecorrigeerd voor inflatie (Alle bedragen werden omgezet (geherwaardeerd) naar prijzen van 2023 op basis van de Belgische consumptieprijsindex (Statbel, basisjaar 2013 = 100). | C32: =C28*C25 -> 3779567.7 | D32: =D28*D25 -> 3866726.6 | E32: =E28*E25 -> 3965755.3 | F32: =F28*F25 -> 4099238 | G32: =G28*G25 -> 4198561.9 | H32: =H28*H25 -> 4567592.2 | I32: =I28*I25 -> 4810018.9 | J32: =J28*J25 -> 4871979.1 | ... W32: =W28*W25 -> 5333723.9
C33: 100 | D33: =(D32/C32)*C33 -> 102.30606 | E33: =(E32/D32)*D33 -> 104.92616 | F33: =(F32/E32)*E33 -> 108.45785 | G33: =(G32/F32)*F33 -> 111.08577 | H33: =(H32/G32)*G33 -> 120.84959 | I33: =(I32/H32)*H33 -> 127.26373 | J33: =(J32/I32)*I33 -> 128.90308 | K33: =(K32/J32)*J33 -> 126.87244 | ... W33: =(W32/V32)*V33 -> 141.11994
C34: =C32/C7 -> 6.22063 | D34: =D32/D7 -> 6.3300134 | E34: =E32/E7 -> 6.405047 | F34: =F32/F7 -> 6.5183255 | G34: =G32/G7 -> 6.5123163 | H34: =H32/H7 -> 6.9318006 | I34: =I32/I7 -> 7.1611976 | J34: =J32/J7 -> 7.1196018 | ... W34: =W32/W7 -> 6.0532219
A35: Evolutie bijdragen/capita zelfstandigen geïndexeerd | C35: 100 | D35: =(D34/C34)*C35 -> 101.7584 | E35: =(E34/D34)*D35 -> 102.9646 | F35: =(F34/E34)*E35 -> 104.78562 | G35: =(G34/F34)*F35 -> 104.68901 | H35: =(H34/G34)*G35 -> 111.43245 | I35: =(I34/H34)*H35 -> 115.12013 | J35: =(J34/I34)*I35 -> 114.45146 | K35: =(K34/J34)*J35 -> 110.74736 | ... W35: =(W34/V34)*V35 -> 97.308824
A37: Uitgaven zelfstandigen
A38: Evolutie uitgaven zelfstandigen | C38: 3664626.8 | D38: 3920038.4 | E38: 4073959.3 | F38: 4327686.1 | G38: 4522043.5 | H38: 5204101.9 | I38: 5551179.3 | J38: 5857141.9 | K38: 6175800.9 | L38: 6246251.5 | M38: 6496362.7 | N38: 6775370.6 | O38: 6064990.5 | P38: 6139008.7 | Q38: 6679802.9 | R38: 6936231.2 | S38: 7194559.6 | T38: 10831756 | U38: 9855311.2 | V38: 9500092.4 | W38: 9331502 | X38: 10364348 | Y38: 10962657
C39: 100 | D39: =(D38/C38)*C39 -> 106.96965 | E39: =(E38/D38)*D39 -> 111.16983 | F39: =(F38/E38)*E39 -> 118.0935 | G39: =(G38/F38)*F39 -> 123.39711 | H39: =(H38/G38)*G39 -> 142.00906 | I39: =(I38/H38)*H39 -> 151.48007 | J39: =(J38/I38)*I39 -> 159.82915 | K39: =(K38/J38)*J39 -> 168.52469 | ... W39: =(W38/V38)*V39 -> 254.63717
C40: =C38/C7 -> 6.0314536 | D40: =D38/D7 -> 6.4172872 | E40: =E38/E7 -> 6.579806 | F40: =F38/F7 -> 6.8815878 | G40: =G38/G7 -> 7.0140629 | H40: =H38/H7 -> 7.897771 | I40: =I38/I7 -> 8.2646437 | J40: =J38/J7 -> 8.5592563 | ... W40: =W38/W7 -> 10.590284
A41: Evolutie uitgaven / capita zelfstandigen | C41: 100 | D41: =(D40/C40)*C41 -> 106.39702 | E41: =(E40/D40)*D41 -> 109.09155 | F41: =(F40/E40)*E41 -> 114.09501 | G41: =(G40/F40)*F41 -> 116.29142 | H41: =(H40/G40)*G41 -> 130.94308 | I41: =(I40/H40)*H41 -> 137.02574 | J41: =(J40/I40)*I41 -> 141.91034 | K41: =(K40/J40)*J41 -> 147.10574 | ... W41: =(W40/V40)*V41 -> 175.58428
A42: Evolutie uitgaven zelfstandigen geïndexeerd | C42: =C38*C25 -> 5862120.7 | D42: =D38*D25 -> 6141761.3 | E42: =E38*E25 -> 6210386.6 | F42: =F38*F25 -> 6481403.5 | G42: =G38*G25 -> 6651103.1 | H42: =H38*H25 -> 7325224.1 | I42: =I38*I25 -> 7818063.6 | J42: =J38*J25 -> 8072250 | ... W42: =W38*W25 -> 9331502
C43: 100 | D43: =(D42/C42)*C43 -> 104.7703 | E43: =(E42/D42)*D43 -> 105.94095 | F43: =(F42/E42)*E43 -> 110.56414 | G43: =(G42/F42)*F43 -> 113.45899 | H43: =(H42/G42)*G43 -> 124.9586 | I43: =(I42/H42)*H43 -> 133.36579 | J43: =(J42/I42)*I43 -> 137.70187 | K43: =(K42/J42)*J43 -> 140.24156 | ... W43: =(W42/V42)*V43 -> 159.18304
C44: =C42/C7 -> 9.6482156 | D44: =D42/D7 -> 10.054352 | E44: =E42/E7 -> 10.030326 | F44: =F42/F7 -> 10.306281 | G44: =G42/G7 -> 10.31641 | H44: =H42/H7 -> 11.116797 | I44: =I42/I7 -> 11.6396 | J44: =J42/J7 -> 11.796275 | ... W44: =W42/W7 -> 10.590284
A45: Evolutie uitgaven/capita zelfstandigen geïndexeerd | C45: 100 | D45: =(D44/C44)*C45 -> 104.20945 | E45: =(E44/D44)*D45 -> 103.96042 | F45: =(F44/E44)*E45 -> 106.82059 | G45: =(G44/F44)*F45 -> 106.92558 | H45: =(H44/G44)*G45 -> 115.22127 | I45: =(I44/H44)*H45 -> 120.63993 | J45: =(J44/I44)*I45 -> 122.2638 | K45: =(K44/J44)*J45 -> 122.4173 | ... W45: =(W44/V44)*V45 -> 109.76418
A46: Bron bedragen zelfstandigen: Excel-file A. Werknemers_2000-2025, verkregen via FOD S.Z.
A47: Bijdragen werknemers
...

Sheet Julie BS - Cijfers
A1: Beroepssolidariteit | B1: 2003 | C1: 2004 | D1: 2005 | E1: 2006 | F1: 2007 | G1: 2008 | H1: 2009 | I1: 2010 | J1: 2011 | K1: 2012 | L1: 2013 | M1: 2014 | N1: 2015 | O1: 2016 | P1: 2017 | Q1: 2018 | R1: 2019 | S1: 2020 | T1: 2021 | U1: 2022 | V1: 2023 | W1: 2024 | X1: 2025
A2: CPI basisjaar 2013 | B2: 80.03 | C2: 81.71 | D2: 83.98 | E2: 85.48 | F2: 87.04 | G2: 90.95 | H2: 90.9 | I2: 92.89 | J2: 96.17 | K2: 98.9 | L2: 100 | M2: 100.34 | N2: 100.9 | O2: 102.89 | P2: 105.08 | Q2: 107.24 | R2: 108.78 | S2: 109.59 | T2: 112.26 | U2: 123.03 | V2: 128.01583 | W2: 132.04
A3: CPI basisjaar 2024 (132.04 basisjaar 2013) | B3: =(B2/$W$2)*100 -> 60.610421 | C3: =(C2/$W$2)*100 -> 61.882763 | D3: =(D2/$W$2)*100 -> 63.601939 | E3: =(E2/$W$2)*100 -> 64.737958 | F3: =(F2/$W$2)*100 -> 65.919418 | G3: =(G2/$W$2)*100 -> 68.880642 | H3: =(H2/$W$2)*100 -> 68.842775 | I3: =(I2/$W$2)*100 -> 70.349894 | ... V3: =(V2/$W$2)*100 -> 96.952312 | W3: =W2/$W$2*100 -> 100
A4: Omzettingsfactor inflatie | B4: =$W$3/B3 -> 1.6498813 | C4: =$W$3/C3 -> 1.6159589 | D4: =$W$3/D3 -> 1.5722791 | E4: =$W$3/E3 -> 1.5446888 | F4: =$W$3/F3 -> 1.5170037 | G4: =$W$3/G3 -> 1.4517867 | H4: =$W$3/H3 -> 1.4525853 | I4: =$W$3/I3 -> 1.4214663 | ... W4: =$W$3/W3 -> 1
A5: Zelfstandigen
A6: Populatie Z1 | B6: ='Oplijsting (sub)categorieën KSZ'!C17 -> 719122 | C6: ='Oplijsting (sub)categorieën KSZ'!D17 -> 717465 | D6: ='Oplijsting (sub)categorieën KSZ'!E17 -> 719042 | E6: ='Oplijsting (sub)categorieën KSZ'!F17 -> 725720 | F6: ='Oplijsting (sub)categorieën KSZ'!G17 -> 739033 | G6: ='Oplijsting (sub)categorieën KSZ'!H17 -> 750095 | H6: ='Oplijsting (sub)categorieën KSZ'!I17 -> 755876 | I6: ='Oplijsting (sub)categorieën KSZ'!J17 -> 765986 | ... V6: ='Oplijsting (sub)categorieën KSZ'!W17 -> 945199
A7: Populatie Z2 | B7: ='Oplijsting (sub)categorieën KSZ'!C18 -> 853157 | C7: ='Oplijsting (sub)categorieën KSZ'!D18 -> 856519 | D7: ='Oplijsting (sub)categorieën KSZ'!E18 -> 863572 | E7: ='Oplijsting (sub)categorieën KSZ'!F18 -> 877436 | F7: ='Oplijsting (sub)categorieën KSZ'!G18 -> 901280 | G7: ='Oplijsting (sub)categorieën KSZ'!H18 -> 920415 | H7: ='Oplijsting (sub)categorieën KSZ'!I18 -> 930560 | I7: ='Oplijsting (sub)categorieën KSZ'!J18 -> 948805 | ... V7: ='Oplijsting (sub)categorieën KSZ'!W18 -> 1241323
A8: Bijdragen | B8: 2362746.5 | C8: 2467975.6 | D8: 2601500.8 | E8: 2737094.7 | F8: 2854576.1 | G8: 3244981.3 | H8: 3415331.3 | I8: 3535058.1 | J8: 3602228.2 | K8: 3746647.9 | L8: 3917483.8 | M8: 3941423.7 | N8: 4194116.6 | O8: 4301696.9 | P8: 4390940.6 | Q8: 4485777.8 | R8: 4567854.7 | S8: 4257700.3 | T8: 4676583.6 | U8: 4843640.9 | V8: 5333723.9 | W8: 5627778.5 | X8: 5751656.2
A9: Uitgaven | B9: 3664626.8 | C9: 3920038.4 | D9: 4073959.3 | E9: 4327686.1 | F9: 4522043.5 | G9: 5204101.9 | H9: 5551179.3 | I9: 5857141.9 | J9: 6175800.9 | K9: 6246251.5 | L9: 6496362.7 | M9: 6775370.6 | N9: 6064990.5 | O9: 6139008.7 | P9: 6679802.9 | Q9: 6936231.2 | R9: 7194559.6 | S9: 10831756 | T9: 9855311.2 | U9: 9500092.4 | V9: 9331502 | W9: 10364348 | X9: 10962657
A10: Gecorrigeerd voor inflatie
A11: Bijdragen | B11: =B8*B4 -> 3898251.2 | C11: =C8*C4 -> 3988147.1 | D11: =D8*D4 -> 4090285.3 | E11: =E8*E4 -> 4227959.6 | F11: =F8*F4 -> 4330402.4 | G11: =G8*G4 -> 4711020.7 | H11: =H8*H4 -> 4961060 | I11: =I8*I4 -> 5024965.8 | ... V11: =V8*V4 -> 5501389
A12: Uitgaven | B12: =B9*B4 -> 6046199.2 | C12: =C9*C4 -> 6334620.8 | D12: =D9*D4 -> 6405401 | E12: =E9*E4 -> 6684928.3 | F12: =F9*F4 -> 6859956.7 | G12: =G9*G4 -> 7555245.9 | H12: =H9*H4 -> 8063561.3 | I12: =I9*I4 -> 8325729.5 | ... V12: =V9*V4 -> 9624837
A13: Per capita gecorrigeerd voor inflatie Z1
A14: Bijdragen | B14: =B11/B$6 -> 5.4208482 | C14: =C11/C$6 -> 5.5586643 | D14: =D11/D$6 -> 5.6885207 | E14: =E11/E$6 -> 5.8258827 | F14: =F11/F$6 -> 5.8595522 | G14: =G11/G$6 -> 6.2805654 | H14: =H11/H$6 -> 6.5633251 | I14: =I11/I$6 -> 6.5601275 | ... V14: =V11/V$6 -> 5.82035
A15: Uitgaven | B15: =B12/B$6 -> 8.4077516 | C15: =C12/C$6 -> 8.8291705 | D15: =D12/D$6 -> 8.9082432 | E15: =E12/E$6 -> 9.2114428 | F15: =F12/F$6 -> 9.2823415 | G15: =G12/G$6 -> 10.072385 | H15: =H12/H$6 -> 10.667836 | I15: =I12/I$6 -> 10.869297 | ... V15: =V12/V$6 -> 10.182868
A16: Procentuele evolutie | Y16: 2003-2014 | Z16: 2014-2015 | AA16: 2015-2019 | AB16: 2003-2019 | AC16: 2019-2020 | AD16: 2020-2022 | AE16: 2019-2022 | AF16: 2003-2022 | AG16: 2022-2023 | AH16: 2019-2023 | AI16: 2003-2023
A17: Populatie | B17: 100 | C17: =C6/B6*B17 -> 99.76958 | D17: =D6/C6*C17 -> 99.988875 | E17: =E6/D6*D17 -> 100.91751 | F17: =F6/E6*E17 -> 102.76879 | G17: =G6/F6*F17 -> 104.30706 | H17: =H6/G6*G17 -> 105.11095 | I17: =I6/H6*H17 -> 106.51684 | J17: =J6/I6*I17 -> 107.94997 | ... V17: =V6/U6*U17 -> 131.43792
A18: Bijdragen | B18: 100 | C18: =C14/B14*B18 -> 102.54233 | D18: =D14/C14*C18 -> 104.93783 | E18: =E14/D14*D18 -> 107.47179 | F18: =F14/E14*E18 -> 108.0929 | G18: =G14/F14*F18 -> 115.85946 | H18: =H14/G14*G18 -> 121.07561 | I18: =I14/H14*H18 -> 121.01662 | J18: =J14/I14*I18 -> 117.52892 | ... V18: =V14/U14*U18 -> 107.36973 | Y18: =M18-B18 -> 18.776849 | Z18: =N18-M18 -> 4.494753 | AA18: =R18-N18 -> -8.347918 | AB18: =R18-B18 -> 14.923684 | AC18: =S18-R18 -> -11.648218 | AD18: =U18-S18 -> -3.452834 | AE18: =U18-R18 -> -15.101052 | AF18: =U18-B18 -> -0.17736794 | AG18: =V18-U18 -> 7.5470963 | AH18: =V18-R18 -> -7.5539554 | AI18: =(V18-B18) -> 7.3697283
A19: Uitgaven | B19: 100 | C19: =C15/B15*B19 -> 105.01227 | D19: =D15/C15*C19 -> 105.95274 | E19: =E15/D15*D19 -> 109.55893 | F19: =F15/E15*E19 -> 110.40218 | G19: =G15/F15*F19 -> 119.7988 | H19: =H15/G15*G19 -> 126.88096 | I19: =I15/H15*H19 -> 129.2771 | J19: =J15/I15*I19 -> 129.91348 | ... V19: =V15/U15*U19 -> 121.11286 | Y19: =M19-B19 -> 31.643405 | Z19: =N19-M19 -> -16.71165 | AA19: =R19-N19 -> 1.7730791 | AB19: =R19-B19 -> 16.704834 | AC19: =S19-R19 -> 52.693184 | AD19: =U19-S19 -> -43.165196 | AE19: =U19-R19 -> 9.5279874 | AF19: =U19-B19 -> 26.232821 | AG19: =V19-U19 -> -5.1199629 | AH19: =V19-R19 -> 4.4080245 | AI19: =(V19-B19) -> 21.112858
A20: Ratio bijdragen/uitgaven | B20: =B14/B15 -> 0.6447441 | C20: =C14/C15 -> 0.62957944 | D20: =D14/D15 -> 0.63856819 | E20: =E14/E15 -> 0.63246148 | F20: =F14/F15 -> 0.63125799 | G20: =G14/G15 -> 0.623543 | H20: =H14/H15 -> 0.61524428 | I20: =I14/I15 -> 0.60354661 | ... V20: =V14/V15 -> 0.57158257 | Y20: =(M20-B20)/B20 -> -0.097737949 | Z20: =(N20-M20)/M20 -> 0.1887494 | AA20: =(R20-N20)/N20 -> -0.081883712 | AB20: =(R20-B20)/B20 -> -0.015262009 | AE20: =(U20-R20)/R20 -> -0.19696212 | AF20: =(U20-B20)/B20 -> -0.20921809 | AG20: =(V20-U20)/U20 -> 0.12107553 | AH20: =(V20-R20)/V20 -> -0.11078266 | AI20: =(V20-B20)/B20 -> -0.11347375
A21: Tekort | B21: =1-B20 -> 0.3552559 | C21: =1-C20 -> 0.37042056 | D21: =1-D20 -> 0.36143181 | E21: =1-E20 -> 0.36753852 | F21: =1-F20 -> 0.36874201 | G21: =1-G20 -> 0.376457 | H21: =1-H20 -> 0.38475572 | I21: =1-I20 -> 0.39645339 | ... V21: =1-V20 -> 0.42841743
A22: Per capita gecorrigeerd voor inflatie Z2
A23: Bijdragen | B23: =B11/B$7 -> 4.5692073 | C23: =C11/C$7 -> 4.6562272 | D23: =D11/D$7 -> 4.7364729 | E23: =E11/E$7 -> 4.818539 | F23: =F11/F$7 -> 4.8047249 | G23: =G11/G$7 -> 5.1183658 | H23: =H11/H$7 -> 5.3312628 | I23: =I11/I$7 -> 5.2960996 | ... V23: =V11/V$7 -> 4.4318755
A24: Uitgaven | B24: =B12/B$7 -> 7.0868541 | C24: =C12/C$7 -> 7.3957739 | D24: =D12/D$7 -> 7.4173329 | E24: =E12/E$7 -> 7.6187075 | F24: =F12/F$7 -> 7.611349 | G24: =G12/G$7 -> 8.2085211 | H24: =H12/H$7 -> 8.6652782 | I24: =I12/I$7 -> 8.7749638 | ... V24: =V12/V$7 -> 7.7536926
A25: Procentuele evolutie
A26: Populatie | B26: 100 | C26: =C7/B7*B26 -> 100.39407 | D26: =D7/C7*C26 -> 101.22076 | E26: =E7/D7*D26 -> 102.84578 | F26: =F7/E7*E26 -> 105.64058 | G26: =G7/F7*F26 -> 107.88343 | H26: =H7/G7*G26 -> 109.07254 | I26: =I7/H7*H26 -> 111.21107 | J26: =J7/I7*I26 -> 113.19745 | ... V26: =V7/U7*U26 -> 145.4976
A27: Bijdragen | B27: 100 | C27: =C23/B23*B27 -> 101.90448 | D27: =D23/C23*C27 -> 103.66071 | E27: =E23/D23*D27 -> 105.45678 | F27: =F23/E23*E27 -> 105.15445 | G27: =G23/F23*F27 -> 112.01868 | H27: =H23/G23*G27 -> 116.67807 | I27: =I23/H23*H27 -> 115.9085 | J27: =J23/I23*I27 -> 112.08065 | ... V27: =V23/U23*U27 -> 96.994406 | Y27: =M27-B27 -> 12.310327 | Z27: =N27-M27 -> 4.2381407 | AA27: =R27-N27 -> -9.8488728 | AB27: =R27-B27 -> 6.6995946 | AC27: =S27-R27 -> -11.330293 | AD27: =U27-S27 -> -4.290663 | AE27: =U27-R27 -> -15.620956 | AF27: =U27-B27 -> -8.9213614 | AG27: =V27-U27 -> 5.9157676 | AH27: =V27-R27 -> -9.7051885 | AI27: =(V27-B27) -> -3.0055938
A28: Uitgaven | B28: 100 | C28: =C24/B24*B28 -> 104.35905 | D28: =D24/C24*C28 -> 104.66327 | E28: =E24/D24*D28 -> 107.50479 | F28: =F24/E24*E28 -> 107.40096 | G28: =G24/F24*F28 -> 115.82743 | H28: =H24/G24*G28 -> 122.27256 | I28: =I24/H24*H28 -> 123.8203 | J28: =J24/I24*I28 -> 123.89109 | ... V28: =V24/U24*U28 -> 109.40951 | Y28: =M28-B28 -> 24.476394 | Z28: =N28-M28 -> -15.812925 | AA28: =R28-N28 -> -0.31018571 | AB28: =R28-B28 -> 8.3532834 | AC28: =S28-R28 -> 48.076615 | AD28: =U28-S28 -> -41.254479 | AE28: =U28-R28 -> 6.8221361 | AF28: =U28-B28 -> 15.17542 | AG28: =V28-U28 -> -5.7659056 | AH28: =V28-R28 -> 1.0562305 | AI28: =(V28-B28) -> 9.4095139
A29: Ratio bijdragen/uitgaven | B29: =B23/B24 -> 0.6447441 | C29: =C23/C24 -> 0.62957944 | D29: =D23/D24 -> 0.63856819 | E29: =E23/E24 -> 0.63246148 | F29: =F23/F24 -> 0.63125799 | G29: =G23/G24 -> 0.623543 | H29: =H23/H24 -> 0.61524428 | I29: =I23/I24 -> 0.60354661 | ... V29: =V23/V24 -> 0.57158257 | Y29: =(M29-B29)/B29 -> -0.097737949 | Z29: =(N29-M29)/M29 -> 0.1887494 | AA29: =(R29-N29)/N29 -> -0.081883712 | AB29: =(R29-B29)/B29 -> -0.015262009 | AE29: =(U29-R29)/R29 -> -0.19696212 | AF29: =(U29-B29)/B29 -> -0.20921809 | AG29: =(V29-U29)/U29 -> 0.12107553 | AH29: =(V29-R29)/V29 -> -0.11078266 | AI29: =(V29-B29)/B29 -> -0.11347375
A30: Tekort | B30: =1-B29 -> 0.3552559 | C30: =1-C29 -> 0.37042056 | D30: =1-D29 -> 0.36143181 | E30: =1-E29 -> 0.36753852 | F30: =1-F29 -> 0.36874201 | G30: =1-G29 -> 0.376457 | H30: =1-H29 -> 0.38475572 | I30: =1-I29 -> 0.39645339 | ... V30: =1-V29 -> 0.42841743
A32: Werknemers
A33: Populatie W1 | B33: ='Oplijsting (sub)categorieën KSZ'!C15 -> 3416845 | C33: ='Oplijsting (sub)categorieën KSZ'!D15 -> 3446922 | D33: ='Oplijsting (sub)categorieën KSZ'!E15 -> 3488326 | E33: ='Oplijsting (sub)categorieën KSZ'!F15 -> 3552305 | F33: ='Oplijsting (sub)categorieën KSZ'!G15 -> 3632158 | G33: ='Oplijsting (sub)categorieën KSZ'!H15 -> 3664695 | H33: ='Oplijsting (sub)categorieën KSZ'!I15 -> 3650975 | I33: ='Oplijsting (sub)categorieën KSZ'!J15 -> 3702275 | ... V33: ='Oplijsting (sub)categorieën KSZ'!W15 -> 3992877
A34: Populatie W2 | B34: ='Oplijsting (sub)categorieën KSZ'!C16 -> 3431288 | C34: ='Oplijsting (sub)categorieën KSZ'!D16 -> 3460962 | D34: ='Oplijsting (sub)categorieën KSZ'!E16 -> 3501575 | E34: ='Oplijsting (sub)categorieën KSZ'!F16 -> 3566422 | F34: ='Oplijsting (sub)categorieën KSZ'!G16 -> 3646646 | G34: ='Oplijsting (sub)categorieën KSZ'!H16 -> 3679558 | H34: ='Oplijsting (sub)categorieën KSZ'!I16 -> 3665867 | I34: ='Oplijsting (sub)categorieën KSZ'!J16 -> 3717768 | ... V34: ='Oplijsting (sub)categorieën KSZ'!W16 -> 4015175
A35: Bijdragen | B35: 32469268 | C35: 33123849 | D35: 34202276 | E35: 35153662 | F35: 37103312 | G35: 38476949 | H35: 39261165 | I35: 39580644 | J35: 41462766 | K35: 43343819 | L35: 44275103 | M35: 45842493 | N35: 47640683 | O35: 47640622 | P35: 48995748 | Q35: 49961681 | R35: 51749904 | S35: 50773064 | T35: 53722777 | U35: 58532826 | V35: 62867872 | W35: 65768583 | X35: 68200926
A36: Uitgaven | B36: 45740072 | C36: 49471194 | D36: 51489775 | E36: 53137695 | F36: 55551744 | G36: 55597965 | H36: 60005317 | I36: 62498799 | J36: 65753434 | K36: 67089304 | L36: 69743795 | M36: 73219534 | N36: 63212126 | O36: 65299033 | P36: 68913399 | Q36: 70920704 | R36: 73329307 | S36: 81169680 | T36: 81725543 | U36: 86385196 | V36: 93354528 | W36: 99309274 | X36: 1.0542195e+08
A37: Gecorrigeerd voor inflatie
A38: Bijdragen | B38: =B35*B4 -> 53570439 | C38: =C35*C4 -> 53526777 | D38: =D35*D4 -> 53775525 | E38: =E35*E4 -> 54301469 | F38: =F35*F4 -> 56285861 | G38: =G35*G4 -> 55860322 | H38: =H35*H4 -> 57030190 | I38: =I35*I4 -> 56262549 | ... V38: =V35*V4 -> 64844118
A39: Uitgaven | B39: =B36*B4 -> 75465689 | C39: =C36*C4 -> 79943416 | D39: =D36*D4 -> 80956298 | E39: =E36*E4 -> 82081203 | F39: =F36*F4 -> 84272200 | G39: =G36*G4 -> 80716385 | H39: =H36*H4 -> 87162839 | I39: =I36*I4 -> 88839934 | ... V39: =V36*V4 -> 96289120
A40: Per capita gecorrigeerd voor inflatie W1
A41: Bijdragen | B41: =B38/B$33 -> 15.678334 | C41: =C38/C$33 -> 15.528862 | D41: =D38/D$33 -> 15.415854 | E41: =E38/E$33 -> 15.286263 | F41: =F38/F$33 -> 15.496534 | G41: =G38/G$33 -> 15.24283 | H41: =H38/H$33 -> 15.620537 | I41: =I38/I$33 -> 15.19675 | ... V41: =V38/V$33 -> 16.239949
...

Sheet Julie NS - cijfers
A1: Nationale solidariteit | B1: 2000 | C1: 2001 | D1: 2002 | E1: 2003 | F1: 2004 | G1: 2005 | H1: 2006 | I1: 2007 | J1: 2008 | K1: 2009 | L1: 2010 | M1: 2011 | N1: 2012 | O1: 2013 | P1: 2014 | Q1: 2015 | R1: 2016 | S1: 2017 | T1: 2018 | U1: 2019 | V1: 2020 | W1: 2021 | X1: 2022 | Y1: 2023 | Z1: 2024
A2: Zelfstandigen | AB2: 2000-2007 | AC2: 2007-2009 | AD2: 2009-2014 | AE2: 2014-2015 | AF2: 2015-2019 | AG2: 2019-2020 | AH2: 2020-2022 | AI2: 2019-2022 | AJ2: 2022-2024 | AK2: 2000-2024 | AM2: 2003-2023
A3: Bijdragen | B3: 0.62936202 | C3: 0.64287331 | D3: 0.64242937 | E3: 0.64637248 | F3: 0.62836384 | G3: 0.61982132 | H3: 0.61533014 | I3: 0.59370584 | J3: 0.5988992 | K3: 0.60984259 | L3: 0.57909718 | M3: 0.57269891 | N3: 0.57699805 | O3: 0.57450181 | P3: 0.56527134 | Q3: 0.66710817 | R3: 0.66518781 | S3: 0.63313136 | T3: 0.62279716 | U3: 0.62028072 | V3: 0.40059676 | W3: 0.43537367 | X3: 0.56218023 | Y3: 0.54663249 | Z3: 0.54675841 | AB3: =I3-B3 -> -0.035656178 | AC3: =K3-I3 -> 0.016136756 | AD3: =P3-K3 -> -0.044571257 | AE3: =Q3-P3 -> 0.10183683 | AF3: =U3-Q3 -> -0.046827449 | AG3: =V3-U3 -> -0.21968396 | AH3: =X3-V3 -> 0.16158347 | AI3: =X3-U3 -> -0.058100489 | AJ3: =Z3-X3 -> -0.015421817 | AK3: =Z3-B3 -> -0.082603604 | AM3: =Y3-E3 -> -0.099739988
A4: Toelagen van publieke overheden | B4: 0.28796942 | C4: 0.29270119 | D4: 0.28555547 | E4: 0.28559352 | F4: 0.27060879 | G4: 0.25857525 | H4: 0.24806478 | I4: 0.23373937 | J4: 0.2303697 | K4: 0.226933 | L4: 0.24871676 | M4: 0.2271822 | N4: 0.27063721 | O4: 0.27861569 | P4: 0.28622559 | Q4: 0.22008025 | R4: 0.21845444 | S4: 0.053371634 | T4: 0.051252942 | U4: 0.051150072 | V4: 0.36838678 | W4: 0.29693015 | X4: 0.099814237 | Y4: 0.12204761 | Z4: 0.090849798 | AB4: =I4-B4 -> -0.054230058 | AC4: =K4-I4 -> -0.0068063648 | AD4: =P4-K4 -> 0.059292587 | AE4: =Q4-P4 -> -0.066145342 | AF4: =U4-Q4 -> -0.16893017 | AG4: =V4-U4 -> 0.31723671 | AH4: =X4-V4 -> -0.26857254 | AI4: =X4-U4 -> 0.048664165 | AJ4: =Z4-X4 -> -0.0089644391 | AK4: =Z4-B4 -> -0.19711963 | AM4: =Y4-E4 -> -0.16354591
A5: Alternatieve financiering | B5: 0.053677654 | C5: 0.034082381 | D5: 0.040723968 | E5: 0.037876166 | F5: 0.068990635 | G5: 0.089062626 | H5: 0.10354957 | I5: 0.13825126 | J5: 0.14839833 | K5: 0.15164586 | L5: 0.15600212 | M5: 0.17736524 | N5: 0.1442761 | O5: 0.14128956 | P5: 0.14348022 | Q5: 0.10721073 | R5: 0.1070623 | S5: 0.3065767 | T5: 0.31987655 | U5: 0.32180124 | V5: 0.22833433 | W5: 0.26424139 | X5: 0.33642157 | Y5: 0.32597617 | Z5: 0.35469796 | AB5: =I5-B5 -> 0.084573609 | AC5: =K5-I5 -> 0.013394602 | AD5: =P5-K5 -> -0.0081656471 | AE5: =Q5-P5 -> -0.036269491 | AF5: =U5-Q5 -> 0.21459051 | AG5: =V5-U5 -> -0.093466912 | AH5: =X5-V5 -> 0.10808724 | AI5: =X5-U5 -> 0.01462033 | AJ5: =Z5-X5 -> 0.018276394 | AK5: =Z5-B5 -> 0.30102031 | AM5: =Y5-E5 -> 0.2881
A6: Overige financiering | B6: 0.028990906 | C6: 0.030343126 | D6: 0.031291192 | E6: 0.030157835 | F6: 0.032036736 | G6: 0.032540802 | H6: 0.03305551 | I6: 0.034303533 | J6: 0.022332774 | K6: 0.01157854 | L6: 0.016183937 | M6: 0.022753652 | N6: 0.008088634 | O6: 0.0055929374 | P6: 0.0050228559 | Q6: 0.0056008584 | R6: 0.0092954504 | S6: 0.0069203006 | T6: 0.0060733474 | U6: 0.0067679694 | V6: 0.0026821369 | W6: 0.0034547937 | X6: 0.0015839646 | Y6: 0.0053437311 | Z6: 0.0076938265 | AB6: =I6-B6 -> 0.0053126271 | AC6: =K6-I6 -> -0.022724994 | AD6: =P6-K6 -> -0.0065556837 | AE6: =Q6-P6 -> 0.00057800244 | AF6: =U6-Q6 -> 0.0011671111 | AG6: =V6-U6 -> -0.0040858325 | AH6: =X6-V6 -> -0.0010981724 | AI6: =X6-U6 -> -0.0051840049 | AJ6: =Z6-X6 -> 0.0061098619 | AK6: =Z6-B6 -> -0.02129708 | AM6: =Y6-E6 -> -0.024814104
A7: Aandeel nationale solidariteit - zelfstandigen | B7: =B4+B5 -> 0.34164708 | C7: =C4+C5 -> 0.32678357 | D7: =D4+D5 -> 0.32627944 | E7: =E4+E5 -> 0.32346968 | F7: =F4+F5 -> 0.33959942 | G7: =G4+G5 -> 0.34763788 | H7: =H4+H5 -> 0.35161435 | I7: =I4+I5 -> 0.37199063 | ... Z7: =Z4+Z5 -> 0.44554776 | AB7: =I7-B7 -> 0.030343551 | AC7: =K7-I7 -> 0.0065882372 | AD7: =P7-K7 -> 0.05112694 | AE7: =Q7-P7 -> -0.10241483 | AF7: =U7-Q7 -> 0.045660338 | AG7: =V7-U7 -> 0.22376979 | AH7: =X7-V7 -> -0.1604853 | AI7: =X7-U7 -> 0.063284494 | AJ7: =Z7-X7 -> 0.0093119554 | AK7: =Z7-B7 -> 0.10390068 | AM7: =Y7-E7 -> 0.12455409
A8: Aandeel overheidstoelagen in NS | B8: =B4/B$7 -> 0.84288566 | C8: =C4/C$7 -> 0.8957035 | D8: =D4/D$7 -> 0.87518684 | E8: =E4/E$7 -> 0.8829066 | F8: =F4/F$7 -> 0.79684702 | G8: =G4/G$7 -> 0.74380632 | H8: =H4/H$7 -> 0.70550245 | I8: =I4/I$7 -> 0.62834746 | ... Z8: =Z4/Z$7 -> 0.20390586
A9: Aandeel alternatieve financiering in NS | B9: =B5/B$7 -> 0.15711434 | C9: =C5/C$7 -> 0.1042965 | D9: =D5/D$7 -> 0.12481316 | E9: =E5/E$7 -> 0.1170934 | F9: =F5/F$7 -> 0.20315298 | G9: =G5/G$7 -> 0.25619368 | H9: =H5/H$7 -> 0.29449755 | I9: =I5/I$7 -> 0.37165254 | ... Z9: =Z5/Z$7 -> 0.79609414
A10: Procentuele evolutie
A11: Bijdragen | B11: 100 | C11: =C3/B3*B11 -> 102.14682 | D11: =D3/C3*C11 -> 102.07629 | E11: =E3/D3*D11 -> 102.70281 | F11: =F3/E3*E11 -> 99.841399 | G11: =G3/F3*F11 -> 98.484069 | H11: =H3/G3*G11 -> 97.77046 | I11: =I3/H3*H11 -> 94.334552 | J11: =J3/I3*I11 -> 95.159731 | ... Z11: =Z3/Y3*Y11 -> 86.875026 | AB11: =I11-B11 -> -5.6654481 | AC11: =K11-I11 -> 2.5639864 | AD11: =P11-K11 -> -7.0819744 | AE11: =Q11-P11 -> 16.180962 | AF11: =U11-Q11 -> -7.4404631 | AG11: =V11-U11 -> -34.905818 | AH11: =X11-V11 -> 25.67417 | AI11: =X11-U11 -> -9.2316486 | AJ11: =Z11-X11 -> -2.450389 | AK11: =Z11-B11 -> -13.124974 | AM11: =Y11-E11 -> -15.847793
A12: Toelagen van publieke overheden | B12: 100 | C12: =C4/B4*B12 -> 101.64315 | D12: =D4/C4*C12 -> 99.161733 | E12: =E4/D4*D12 -> 99.174945 | F12: =F4/E4*E12 -> 93.971361 | G12: =G4/F4*F12 -> 89.792606 | H12: =H4/G4*G12 -> 86.142751 | I12: =I4/H4*H12 -> 81.168119 | J12: =J4/I4*I12 -> 79.997973 | ... Z12: =Z4/Y4*Y12 -> 31.548418 | AB12: =I12-B12 -> -18.831881 | AC12: =K12-I12 -> -2.363572 | AD12: =P12-K12 -> 20.58989 | AE12: =Q12-P12 -> -22.969571 | AF12: =U12-Q12 -> -58.662539 | AG12: =V12-U12 -> 110.16333 | AH12: =X12-V12 -> -93.264256 | AI12: =X12-U12 -> 16.899073 | AJ12: =Z12-X12 -> -3.1129829 | AK12: =Z12-B12 -> -68.451582 | AM12: =Y12-E12 -> -56.792804
A13: Alternatieve financiering | B13: 100 | C13: =C5/B5*B13 -> 63.494543 | D13: =D5/C5*C13 -> 75.867637 | E13: =E5/D5*D13 -> 70.562261 | F13: =F5/E5*E13 -> 128.52767 | G13: =G5/F5*F13 -> 165.92123 | H13: =H5/G5*G13 -> 192.91001 | I13: =I5/H5*H13 -> 257.55832 | J13: =J5/I5*I13 -> 276.46202 | ... Z13: =Z5/Y5*Y13 -> 660.7926 | AB13: =I13-B13 -> 157.55832 | AC13: =K13-I13 -> 24.953777 | AD13: =P13-K13 -> -15.212377 | AE13: =Q13-P13 -> -67.569069 | AF13: =U13-Q13 -> 399.77625 | AG13: =V13-U13 -> -174.1263 | AH13: =X13-V13 -> 201.36357 | AI13: =X13-U13 -> 27.237274 | AJ13: =Z13-X13 -> 34.048423 | AK13: =Z13-B13 -> 560.7926 | AM13: =Y13-E13 -> 536.72242
A14: Overige financiering | B14: 100 | C14: =C6/B6*B14 -> 104.66429 | D14: =D6/C6*C14 -> 107.93451 | E14: =E6/D6*D14 -> 104.02515 | F14: =F6/E6*E14 -> 110.50616 | G14: =G6/F6*F14 -> 112.24486 | H14: =H6/G6*G14 -> 114.02027 | I14: =I6/H6*H14 -> 118.32515 | J14: =J6/I6*I14 -> 77.03372 | ... Z14: =Z6/Y6*Y14 -> 26.538758 | AB14: =I14-B14 -> 18.32515 | AC14: =K14-I14 -> -78.386628 | AD14: =P14-K14 -> -22.612897 | AE14: =Q14-P14 -> 1.9937371 | AF14: =U14-Q14 -> 4.0257833 | AG14: =V14-U14 -> -14.093497 | AH14: =X14-V14 -> -3.7879891 | AI14: =X14-U14 -> -17.881486 | AJ14: =Z14-X14 -> 21.075098 | AK14: =Z14-B14 -> -73.461242 | AM14: =Y14-E14 -> -85.592715
A15: Evolutie nationale solidariteit - zelfstandigen | B15: 100 | C15: =C7/B7*B15 -> 95.649455 | D15: =D7/C7*C15 -> 95.501897 | E15: =E7/D7*D15 -> 94.679482 | F15: =F7/E7*E15 -> 99.400652 | G15: =G7/F7*F15 -> 101.7535 | H15: =H7/G7*G15 -> 102.91742 | I15: =I7/H7*H15 -> 108.88155 | J15: =J7/I7*I15 -> 110.86529 | ... Z15: =Z7/Y7*Y15 -> 130.4117 | AB15: =I15-B15 -> 8.8815486 | AC15: =K15-I15 -> 1.9283751 | AD15: =P15-K15 -> 14.96484 | AE15: =Q15-P15 -> -29.976792 | AF15: =U15-Q15 -> 13.364767 | AG15: =V15-U15 -> 65.497353 | AH15: =X15-V15 -> -46.974 | AI15: =X15-U15 -> 18.523353 | AJ15: =Z15-X15 -> 2.7256066 | AK15: =Z15-B15 -> 30.4117 | AM15: =Y15-E15 -> 36.456946
A16: Werknemers
A17: Bijdragen | B17: 0.72313125 | C17: 0.73589716 | D17: 0.72424717 | E17: 0.72299185 | F17: 0.67482368 | G17: 0.66178949 | H17: 0.65898687 | I17: 0.65491146 | J17: 0.68282476 | K17: 0.68564004 | L17: 0.64409502 | M17: 0.63943923 | N17: 0.64341415 | O17: 0.63493053 | P17: 0.62834991 | Q17: 0.74957381 | R17: 0.73951012 | S17: 0.70484982 | T17: 0.70959035 | U17: 0.69651687 | V17: 0.62120133 | W17: 0.65310123 | X17: 0.68425385 | Y17: 0.67169946 | Z17: 0.66170133 | AB17: =I17-B17 -> -0.068219784 | AC17: =K17-I17 -> 0.030728573 | AD17: =P17-K17 -> -0.057290125 | AE17: =Q17-P17 -> 0.1212239 | AF17: =U17-Q17 -> -0.053056941 | AG17: =V17-U17 -> -0.075315536 | AH17: =X17-V17 -> 0.063052517 | AI17: =X17-U17 -> -0.012263019 | AJ17: =Z17-X17 -> -0.022552523 | AK17: =Z17-B17 -> -0.06142992 | AM17: =Y17-E17 -> -0.051292391
A18: Toelagen van publieke overheden | B18: 0.12191492 | C18: 0.12224094 | D18: 0.11463293 | E18: 0.11601085 | F18: 0.10772123 | G18: 0.10362699 | H18: 0.10180414 | I18: 0.09747033 | J18: 0.10196257 | K18: 0.10216196 | L18: 0.1319611 | M18: 0.10899038 | N18: 0.14634941 | O18: 0.15900649 | P18: 0.16302007 | Q18: 0.1247234 | R18: 0.12528907 | S18: 0.095272286 | T18: 0.079611634 | U18: 0.091605623 | V18: 0.17402758 | W18: 0.11220025 | X18: 0.086908274 | Y18: 0.09601475 | Z18: 0.095468585 | AB18: =I18-B18 -> -0.024444594 | AC18: =K18-I18 -> 0.0046916286 | AD18: =P18-K18 -> 0.060858109 | AE18: =Q18-P18 -> -0.038296668 | AF18: =U18-Q18 -> -0.033117776 | AG18: =V18-U18 -> 0.082421958 | AH18: =X18-V18 -> -0.087119308 | AI18: =X18-U18 -> -0.0046973499 | AJ18: =Z18-X18 -> 0.0085603117 | AK18: =Z18-B18 -> -0.026446339 | AM18: =Y18-E18 -> -0.0199961
A19: Alternatieve financiering | B19: 0.08756741 | C19: 0.080253667 | D19: 0.097114678 | E19: 0.098596472 | F19: 0.15316626 | G19: 0.1720455 | H19: 0.17967511 | I19: 0.18489506 | J19: 0.16518077 | K19: 0.16147565 | L19: 0.17120459 | M19: 0.19610592 | N19: 0.16744094 | O19: 0.16565298 | P19: 0.16408866 | Q19: 0.088146149 | R19: 0.097786595 | S19: 0.1657773 | T19: 0.17694586 | U19: 0.17869019 | V19: 0.17641793 | W19: 0.20524126 | X19: 0.20183828 | Y19: 0.20686426 | Z19: 0.21497806 | AB19: =I19-B19 -> 0.097327652 | AC19: =K19-I19 -> -0.023419408 | AD19: =P19-K19 -> 0.0026130025 | AE19: =Q19-P19 -> -0.075942507 | AF19: =U19-Q19 -> 0.090544044 | AG19: =V19-U19 -> -0.0022722597 | AH19: =X19-V19 -> 0.025420344 | AI19: =X19-U19 -> 0.023148084 | AJ19: =Z19-X19 -> 0.013139786 | AK19: =Z19-B19 -> 0.12741065 | AM19: =Y19-E19 -> 0.10826779
A20: Overige financiering | B20: 0.067386418 | C20: 0.061608236 | D20: 0.06400522 | E20: 0.062400827 | F20: 0.064288828 | G20: 0.062538015 | H20: 0.059533877 | I20: 0.062723144 | J20: 0.0500319 | K20: 0.050722351 | L20: 0.052739294 | M20: 0.05546447 | N20: 0.042795501 | O20: 0.040409996 | P20: 0.044541364 | Q20: 0.037556641 | R20: 0.037414224 | S20: 0.034100598 | T20: 0.033852153 | U20: 0.033187314 | V20: 0.028353152 | W20: 0.029457261 | X20: 0.026999599 | Y20: 0.025421529 | Z20: 0.027852024 | AB20: =I20-B20 -> -0.0046632735 | AC20: =K20-I20 -> -0.012000794 | AD20: =P20-K20 -> -0.0061809867 | AE20: =Q20-P20 -> -0.0069847229 | AF20: =U20-Q20 -> -0.0043693274 | AG20: =V20-U20 -> -0.004834162 | AH20: =X20-V20 -> -0.001353553 | AI20: =X20-U20 -> -0.006187715 | AJ20: =Z20-X20 -> 0.00085242531 | AK20: =Z20-B20 -> -0.039534394 | AM20: =Y20-E20 -> -0.036979298
A21: Aandeel nationale solidariteit - werknemers | B21: =B18+B19 -> 0.20948233 | C21: =C18+C19 -> 0.20249461 | D21: =D18+D19 -> 0.21174761 | E21: =E18+E19 -> 0.21460732 | F21: =F18+F19 -> 0.26088749 | G21: =G18+G19 -> 0.2756725 | H21: =H18+H19 -> 0.28147925 | I21: =I18+I19 -> 0.28236539 | ... Z21: =Z18+Z19 -> 0.31044665 | AB21: =I21-B21 -> 0.072883058 | AC21: =K21-I21 -> -0.018727779 | AD21: =P21-K21 -> 0.063471111 | AE21: =Q21-P21 -> -0.11423918 | AF21: =U21-Q21 -> 0.057426268 | AG21: =V21-U21 -> 0.080149698 | AH21: =X21-V21 -> -0.061698964 | AI21: =X21-U21 -> 0.018450734 | AJ21: =Z21-X21 -> 0.021700097 | AK21: =Z21-B21 -> 0.10096431 | AM21: =Y21-E21 -> 0.088271689
A22: Aandeel overheidstoelagen in NS | B22: =B18/B$21 -> 0.58198189 | C22: =C18/C$21 -> 0.60367504 | D22: =D18/D$21 -> 0.54136588 | E22: =E18/E$21 -> 0.54057265 | F22: =F18/F$21 -> 0.41290301 | G22: =G18/G$21 -> 0.37590617 | H22: =H18/H$21 -> 0.36167547 | I22: =I18/I$21 -> 0.3451922 | ... Z22: =Z18/Z$21 -> 0.3075201
A23: Aandeel alternatieve financiering in NS | B23: =B19/B$21 -> 0.41801811 | C23: =C19/C$21 -> 0.39632496 | D23: =D19/D$21 -> 0.45863412 | E23: =E19/E$21 -> 0.45942735 | F23: =F19/F$21 -> 0.58709699 | G23: =G19/G$21 -> 0.62409383 | H23: =H19/H$21 -> 0.63832453 | I23: =I19/I$21 -> 0.6548078 | ... Z23: =Z19/Z$21 -> 0.6924799
A24: Procentuele evolutie
A25: Bijdragen | B25: 100 | C25: =C17/B17*B25 -> 101.76537 | D25: =D17/C17*C25 -> 100.15432 | E25: =E17/D17*D25 -> 99.980723 | F25: =F17/E17*E25 -> 93.319669 | G25: =G17/F17*F25 -> 91.517203 | H25: =H17/G17*G25 -> 91.129635 | I25: =I17/H17*H25 -> 90.566058 | J25: =J17/I17*I25 -> 94.426117 | ... Z25: =Z17/Y17*Y25 -> 91.505011 | AB25: =I25-B25 -> -9.4339422 | AC25: =K25-I25 -> 4.249377 | AD25: =P25-K25 -> -7.9225071 | AE25: =Q25-P25 -> 16.763748 | AF25: =U25-Q25 -> -7.3371108 | AG25: =V25-U25 -> -10.415196 | AH25: =X25-V25 -> 8.7193738 | AI25: =X25-U25 -> -1.695822 | AJ25: =Z25-X25 -> -3.1187316 | AK25: =Z25-B25 -> -8.494989 | AM25: =Y25-E25 -> -7.0930956
A26: Toelagen van publieke overheden | B26: 100 | C26: =C18/B18*B26 -> 100.26741 | D26: =D18/C18*C26 -> 94.026989 | E26: =E18/D18*D26 -> 95.157217 | F26: =F18/E18*E26 -> 88.357705 | G26: =G18/F18*F26 -> 84.999431 | H26: =H18/G18*G26 -> 83.504248 | I26: =I18/H18*H26 -> 79.949466 | J26: =J18/I18*I26 -> 83.634198 | ... Z26: =Z18/Y18*Y26 -> 78.307546 | AB26: =I26-B26 -> -20.050534 | AC26: =K26-I26 -> 3.8482807 | AD26: =P26-K26 -> 49.918506 | AE26: =Q26-P26 -> -31.412617 | AF26: =U26-Q26 -> -27.164661 | AG26: =V26-U26 -> 67.606126 | AH26: =X26-V26 -> -71.4591 | AI26: =X26-U26 -> -3.8529736 | AJ26: =Z26-X26 -> 7.0215454 | AK26: =Z26-B26 -> -21.692454 | AM26: =Y26-E26 -> -16.401683
A27: Alternatieve financiering | B27: 100 | C27: =C19/B19*B27 -> 91.647871 | D27: =D19/C19*C27 -> 110.90276 | E27: =E19/D19*D27 -> 112.59494 | F27: =F19/E19*E27 -> 174.9124 | G27: =G19/F19*F27 -> 196.47207 | H27: =H19/G19*G27 -> 205.18491 | I27: =I19/H19*H27 -> 211.14597 | J27: =J19/I19*I27 -> 188.6327 | ... Z27: =Z19/Y19*Y27 -> 245.50008 | AB27: =I27-B27 -> 111.14597 | AC27: =K27-I27 -> -26.744434 | AD27: =P27-K27 -> 2.9839897 | AE27: =Q27-P27 -> -86.724624 | AF27: =U27-Q27 -> 103.39925 | AG27: =V27-U27 -> -2.5948691 | AH27: =X27-V27 -> 29.029457 | AI27: =X27-U27 -> 26.434588 | AJ27: =Z27-X27 -> 15.005338 | AK27: =Z27-B27 -> 145.50008 | AM27: =Y27-E27 -> 123.63936
A28: Overige financiering | B28: 100 | C28: =C20/B20*B28 -> 91.425302 | D28: =D20/C20*C28 -> 94.982374 | E28: =E20/D20*D28 -> 92.60149 | F28: =F20/E20*E28 -> 95.403243 | G28: =G20/F20*F28 -> 92.805073 | H28: =H20/G20*G28 -> 88.346998 | I28: =I20/H20*H28 -> 93.079802 | J28: =J20/I20*I28 -> 74.246267 | ... Z28: =Z20/Y20*Y28 -> 41.331807 | AB28: =I28-B28 -> -6.9201979 | AC28: =K28-I28 -> -17.808921 | AD28: =P28-K28 -> -9.1724518 | AE28: =Q28-P28 -> -10.365179 | AF28: =U28-Q28 -> -6.4839882 | AG28: =V28-U28 -> -7.1737929 | AH28: =X28-V28 -> -2.0086436 | AI28: =X28-U28 -> -9.1824365 | AJ28: =Z28-X28 -> 1.2649809 | AK28: =Z28-B28 -> -58.668193 | AM28: =Y28-E28 -> -54.876486
A29: Evolutie nationale solidariteit - werknemers | B29: 100 | C29: =C21/B21*B29 -> 96.664288 | D29: =D21/C21*C29 -> 101.08137 | E29: =E21/D21*D29 -> 102.4465 | F29: =F21/E21*E29 -> 124.53914 | G29: =G21/F21*F29 -> 131.59701 | H29: =H21/G21*G29 -> 134.36897 | I29: =I21/H21*H29 -> 134.79198 | J29: =J21/I21*I29 -> 127.52547 | ... Z29: =Z21/Y21*Y29 -> 148.19705 | AB29: =I29-B29 -> 34.791983 | AC29: =K29-I29 -> -8.940028 | AD29: =P29-K29 -> 30.299028 | AE29: =Q29-P29 -> -54.534038 | AF29: =U29-Q29 -> 27.413418 | AG29: =V29-U29 -> 38.260839 | AH29: =X29-V29 -> -29.453063 | AI29: =X29-U29 -> 8.8077757 | AJ29: =Z29-X29 -> 10.358915 | AK29: =Z29-B29 -> 48.197054 | AM29: =Y29-E29 -> 42.138011
A31: Bron: Excel 'A. Werknemers_2000-2025' en 'B.Zelfstandigen_2000-2025' verkregen van FOD SZ

Sheet Julie - Figuren

Sheet Julie BS - gezondheidsindex
A1: Beroepssolidariteit | B1: 2003 | C1: 2004 | D1: 2005 | E1: 2006 | F1: 2007 | G1: 2008 | H1: 2009 | I1: 2010 | J1: 2011 | K1: 2012 | L1: 2013 | M1: 2014 | N1: 2015 | O1: 2016 | P1: 2017 | Q1: 2018 | R1: 2019 | S1: 2020 | T1: 2021 | U1: 2022 | V1: 2023 | W1: 2024 | X1: 2025
A2: GI basisjaar 2013 | B2: 81.45477 | C2: 82.780579 | D2: 84.575819 | E2: 86.07129 | F2: 87.59205 | G2: 91.29114 | H2: 91.82865 | I2: 93.36459 | J2: 96.22119 | K2: 98.77005 | L2: 99.99618 | M2: 100.40083 | N2: 101.45417 | O2: 103.57667 | P2: 105.48833 | Q2: 107.35083 | R2: 108.92417 | S2: 109.99667 | T2: 112.20667 | U2: 122.58833 | V2: 127.895 | W2: 132.09833
A3: GI basisjaar 2024 (132.10 basisjaar 2013) | B3: =(B2/$W$2)*100 -> 61.662223 | C3: =(C2/$W$2)*100 -> 62.665877 | D3: =(D2/$W$2)*100 -> 64.024894 | E3: =(E2/$W$2)*100 -> 65.156984 | F3: =(F2/$W$2)*100 -> 66.308217 | G3: =(G2/$W$2)*100 -> 69.108472 | H3: =(H2/$W$2)*100 -> 69.515374 | I3: =(I2/$W$2)*100 -> 70.678098 | ... V3: =(V2/$W$2)*100 -> 96.818027 | W3: =W2/$W$2*100 -> 100
A4: Omzettingsfactor inflatie | B4: =$W$3/B3 -> 1.6217385 | C4: =$W$3/C3 -> 1.5957648 | D4: =$W$3/D3 -> 1.5618925 | E4: =$W$3/E3 -> 1.5347549 | F4: =$W$3/F3 -> 1.5081087 | G4: =$W$3/G3 -> 1.4470006 | H4: =$W$3/H3 -> 1.4385307 | I4: =$W$3/I3 -> 1.4148655 | ... W4: =$W$3/W3 -> 1
A5: Zelfstandigen
A6: Populatie Z1 | B6: ='Oplijsting (sub)categorieën KSZ'!C17 -> 719122 | C6: ='Oplijsting (sub)categorieën KSZ'!D17 -> 717465 | D6: ='Oplijsting (sub)categorieën KSZ'!E17 -> 719042 | E6: ='Oplijsting (sub)categorieën KSZ'!F17 -> 725720 | F6: ='Oplijsting (sub)categorieën KSZ'!G17 -> 739033 | G6: ='Oplijsting (sub)categorieën KSZ'!H17 -> 750095 | H6: ='Oplijsting (sub)categorieën KSZ'!I17 -> 755876 | I6: ='Oplijsting (sub)categorieën KSZ'!J17 -> 765986 | ... V6: ='Oplijsting (sub)categorieën KSZ'!W17 -> 945199
A7: Populatie Z2 | B7: ='Oplijsting (sub)categorieën KSZ'!C18 -> 853157 | C7: ='Oplijsting (sub)categorieën KSZ'!D18 -> 856519 | D7: ='Oplijsting (sub)categorieën KSZ'!E18 -> 863572 | E7: ='Oplijsting (sub)categorieën KSZ'!F18 -> 877436 | F7: ='Oplijsting (sub)categorieën KSZ'!G18 -> 901280 | G7: ='Oplijsting (sub)categorieën KSZ'!H18 -> 920415 | H7: ='Oplijsting (sub)categorieën KSZ'!I18 -> 930560 | I7: ='Oplijsting (sub)categorieën KSZ'!J18 -> 948805 | ... V7: ='Oplijsting (sub)categorieën KSZ'!W18 -> 1241323
A8: Bijdragen | B8: 2362746.5 | C8: 2467975.6 | D8: 2601500.8 | E8: 2737094.7 | F8: 2854576.1 | G8: 3244981.3 | H8: 3415331.3 | I8: 3535058.1 | J8: 3602228.2 | K8: 3746647.9 | L8: 3917483.8 | M8: 3941423.7 | N8: 4194116.6 | O8: 4301696.9 | P8: 4390940.6 | Q8: 4485777.8 | R8: 4567854.7 | S8: 4257700.3 | T8: 4676583.6 | U8: 4843640.9 | V8: 5333723.9 | W8: 5627778.5 | X8: 5751656.2
A9: Uitgaven | B9: 3664626.8 | C9: 3920038.4 | D9: 4073959.3 | E9: 4327686.1 | F9: 4522043.5 | G9: 5204101.9 | H9: 5551179.3 | I9: 5857141.9 | J9: 6175800.9 | K9: 6246251.5 | L9: 6496362.7 | M9: 6775370.6 | N9: 6064990.5 | O9: 6139008.7 | P9: 6679802.9 | Q9: 6936231.2 | R9: 7194559.6 | S9: 10831756 | T9: 9855311.2 | U9: 9500092.4 | V9: 9331502 | W9: 10364348 | X9: 10962657
A10: Gecorrigeerd voor inflatie
A11: Bijdragen | B11: =B8*B4 -> 3831756.9 | C11: =C8*C4 -> 3938308.6 | D11: =D8*D4 -> 4063264.4 | E11: =E8*E4 -> 4200769.5 | F11: =F8*F4 -> 4305011.1 | G11: =G8*G4 -> 4695489.9 | H11: =H8*H4 -> 4913059 | I11: =I8*I4 -> 5001631.6 | ... V11: =V8*V4 -> 5509019.4
A12: Uitgaven | B12: =B9*B4 -> 5943066.2 | C12: =C9*C4 -> 6255459.3 | D12: =D9*D4 -> 6363086.2 | E12: =E9*E4 -> 6641937.3 | F12: =F9*F4 -> 6819733.2 | G12: =G9*G4 -> 7530338.6 | H12: =H9*H4 -> 7985542 | I12: =I9*I4 -> 8287067.7 | ... V12: =V9*V4 -> 9638186.5
A13: Per capita gecorrigeerd voor inflatie Z1
A14: Bijdragen | B14: =B11/B$6 -> 5.3283822 | C14: =C11/C$6 -> 5.4891996 | D14: =D11/D$6 -> 5.6509417 | E14: =E11/E$6 -> 5.7884163 | F14: =F11/F$6 -> 5.8251946 | G14: =G11/G$6 -> 6.2598603 | H14: =H11/H$6 -> 6.4998214 | I14: =I11/I$6 -> 6.5296645 | ... V14: =V11/V$6 -> 5.8284228
A15: Uitgaven | B15: =B12/B$6 -> 8.2643365 | C15: =C12/C$6 -> 8.7188355 | D15: =D12/D$6 -> 8.8493944 | E15: =E12/E$6 -> 9.1522038 | F15: =F12/F$6 -> 9.2279143 | G15: =G12/G$6 -> 10.03918 | H15: =H12/H$6 -> 10.564619 | I15: =I12/I$6 -> 10.818824 | ... V15: =V12/V$6 -> 10.196992
A16: Procentuele evolutie | Y16: 2003-2014 | Z16: 2014-2015 | AA16: 2015-2019 | AB16: 2003-2019 | AC16: 2019-2020 | AD16: 2020-2022 | AE16: 2019-2022 | AF16: 2003-2022 | AG16: 2022-2023 | AH16: 2019-2023 | AI16: 2003-2023
A17: Populatie | B17: 100 | C17: =C6/B6*B17 -> 99.76958 | D17: =D6/C6*C17 -> 99.988875 | E17: =E6/D6*D17 -> 100.91751 | F17: =F6/E6*E17 -> 102.76879 | G17: =G6/F6*F17 -> 104.30706 | H17: =H6/G6*G17 -> 105.11095 | I17: =I6/H6*H17 -> 106.51684 | J17: =J6/I6*I17 -> 107.94997 | ... V17: =V6/U6*U17 -> 131.43792
A18: Bijdragen | B18: 100 | C18: =C14/B14*B18 -> 103.01813 | D18: =D14/C14*C18 -> 106.05361 | E18: =E14/D14*D18 -> 108.63365 | F18: =F14/E14*E18 -> 109.32389 | G18: =G14/F14*F18 -> 117.48144 | H18: =H14/G14*G18 -> 121.98489 | I18: =I14/H14*H18 -> 122.54497 | J18: =J14/I14*I18 -> 119.55765 | ... V18: =V14/U14*U18 -> 109.38447 | Y18: =M18-B18 -> 20.818177 | Z18: =N18-M18 -> 3.9626955 | AA18: =R18-N18 -> -7.9660247 | AB18: =R18-B18 -> 16.814848 | AC18: =S18-R18 -> -12.08939 | AD18: =U18-S18 -> -2.7596412 | AE18: =U18-R18 -> -14.849031 | AF18: =U18-B18 -> 1.9658168 | AG18: =V18-U18 -> 7.418656 | AH18: =V18-R18 -> -7.4303755 | AI18: =(V18-B18) -> 9.3844728
A19: Uitgaven | B19: 100 | C19: =C15/B15*B19 -> 105.49952 | D19: =D15/C15*C19 -> 107.07931 | E19: =E15/D15*D19 -> 110.74336 | F19: =F15/E15*E19 -> 111.65947 | G19: =G15/F15*F19 -> 121.47593 | H19: =H15/G15*G19 -> 127.83384 | I19: =I15/H15*H19 -> 130.90977 | J19: =J15/I15*I19 -> 132.15597 | ... V19: =V15/U15*U19 -> 123.38549 | Y19: =M19-B19 -> 33.905862 | Z19: =N19-M19 -> -17.566944 | AA19: =R19-N19 -> 2.2863913 | AB19: =R19-B19 -> 18.625309 | AC19: =S19-R19 -> 53.151064 | AD19: =U19-S19 -> -42.833342 | AE19: =U19-R19 -> 10.317722 | AF19: =U19-B19 -> 28.943031 | AG19: =V19-U19 -> -5.5575445 | AH19: =V19-R19 -> 4.7601778 | AI19: =(V19-B19) -> 23.385487
A20: Ratio bijdragen/uitgaven | B20: =B14/B15 -> 0.6447441 | C20: =C14/C15 -> 0.62957944 | D20: =D14/D15 -> 0.63856819 | E20: =E14/E15 -> 0.63246148 | F20: =F14/F15 -> 0.63125799 | G20: =G14/G15 -> 0.623543 | H20: =H14/H15 -> 0.61524428 | I20: =I14/I15 -> 0.60354661 | ... V20: =V14/V15 -> 0.57158257 | Y20: =(M20-B20)/B20 -> -0.097737949 | Z20: =(N20-M20)/M20 -> 0.1887494 | AA20: =(R20-N20)/N20 -> -0.081883712 | AB20: =(R20-B20)/B20 -> -0.015262009 | AE20: =(U20-R20)/R20 -> -0.19696212 | AF20: =(U20-B20)/B20 -> -0.20921809 | AG20: =(V20-U20)/U20 -> 0.12107553 | AH20: =(V20-R20)/V20 -> -0.11078266 | AI20: =(V20-B20)/B20 -> -0.11347375
A21: Tekort | B21: =1-B20 -> 0.3552559 | C21: =1-C20 -> 0.37042056 | D21: =1-D20 -> 0.36143181 | E21: =1-E20 -> 0.36753852 | F21: =1-F20 -> 0.36874201 | G21: =1-G20 -> 0.376457 | H21: =1-H20 -> 0.38475572 | I21: =1-I20 -> 0.39645339 | ... V21: =1-V20 -> 0.42841743
A22: Per capita gecorrigeerd voor inflatie Z2
A23: Bijdragen | B23: =B11/B$7 -> 4.4912682 | C23: =C11/C$7 -> 4.5980399 | D23: =D11/D$7 -> 4.7051832 | E23: =E11/E$7 -> 4.7875509 | F23: =F11/F$7 -> 4.7765523 | G23: =G11/G$7 -> 5.1014921 | H23: =H11/H$7 -> 5.27968 | I23: =I11/I$7 -> 5.2715064 | ... V23: =V11/V$7 -> 4.4380225
A24: Uitgaven | B24: =B12/B$7 -> 6.9659702 | C24: =C12/C$7 -> 7.3033515 | D24: =D12/D$7 -> 7.3683332 | E24: =E12/E$7 -> 7.5697115 | F24: =F12/F$7 -> 7.5667198 | G24: =G12/G$7 -> 8.1814601 | H24: =H12/H$7 -> 8.5814369 | I24: =I12/I$7 -> 8.7342159 | ... V24: =V12/V$7 -> 7.7644469
A25: Procentuele evolutie
A26: Populatie | B26: 100 | C26: =C7/B7*B26 -> 100.39407 | D26: =D7/C7*C26 -> 101.22076 | E26: =E7/D7*D26 -> 102.84578 | F26: =F7/E7*E26 -> 105.64058 | G26: =G7/F7*F26 -> 107.88343 | H26: =H7/G7*G26 -> 109.07254 | I26: =I7/H7*H26 -> 111.21107 | J26: =J7/I7*I26 -> 113.19745 | ... V26: =V7/U7*U26 -> 145.4976
A27: Bijdragen | B27: 100 | C27: =C23/B23*B27 -> 102.37732 | D27: =D23/C23*C27 -> 104.76291 | E27: =E23/D23*D27 -> 106.59686 | F27: =F23/E23*E27 -> 106.35197 | G27: =G23/F23*F27 -> 113.5869 | H27: =H23/G23*G27 -> 117.55433 | I27: =I23/H23*H27 -> 117.37234 | J27: =J23/I23*I27 -> 114.01533 | ... V27: =V23/U23*U27 -> 98.814462 | Y27: =M27-B27 -> 14.24052 | Z27: =N27-M27 -> 3.734904 | AA27: =R27-N27 -> -9.5199993 | AB27: =R27-B27 -> 8.4554249 | AC27: =S27-R27 -> -11.747134 | AD27: =U27-S27 -> -3.6742002 | AE27: =U27-R27 -> -15.421334 | AF27: =U27-B27 -> -6.9659095 | AG27: =V27-U27 -> 5.7803719 | AH27: =V27-R27 -> -9.6409625 | AI27: =(V27-B27) -> -1.1855376
A28: Uitgaven | B28: 100 | C28: =C24/B24*B28 -> 104.84328 | D28: =D24/C24*C28 -> 105.77612 | E28: =E24/D24*D28 -> 108.66701 | F28: =F24/E24*E28 -> 108.62406 | G28: =G24/F24*F28 -> 117.44897 | H28: =H24/G24*G28 -> 123.19084 | I28: =I24/H24*H28 -> 125.38406 | J28: =J24/I24*I28 -> 126.02963 | ... V28: =V24/U24*U28 -> 111.46253 | Y28: =M28-B28 -> 26.615677 | Z28: =N28-M28 -> -16.621791 | AA28: =R28-N28 -> 0.1424403 | AB28: =R28-B28 -> 10.136326 | AC28: =S28-R28 -> 48.489854 | AD28: =U28-S28 -> -40.977953 | AE28: =U28-R28 -> 7.511901 | AF28: =U28-B28 -> 17.648227 | AG28: =V28-U28 -> -6.1856935 | AH28: =V28-R28 -> 1.3262075 | AI28: =(V28-B28) -> 11.462534
A29: Ratio bijdragen/uitgaven | B29: =B23/B24 -> 0.6447441 | C29: =C23/C24 -> 0.62957944 | D29: =D23/D24 -> 0.63856819 | E29: =E23/E24 -> 0.63246148 | F29: =F23/F24 -> 0.63125799 | G29: =G23/G24 -> 0.623543 | H29: =H23/H24 -> 0.61524428 | I29: =I23/I24 -> 0.60354661 | ... V29: =V23/V24 -> 0.57158257 | Y29: =(M29-B29)/B29 -> -0.097737949 | Z29: =(N29-M29)/M29 -> 0.1887494 | AA29: =(R29-N29)/N29 -> -0.081883712 | AB29: =(R29-B29)/B29 -> -0.015262009 | AE29: =(U29-R29)/R29 -> -0.19696212 | AF29: =(U29-B29)/B29 -> -0.20921809 | AG29: =(V29-U29)/U29 -> 0.12107553 | AH29: =(V29-R29)/V29 -> -0.11078266 | AI29: =(V29-B29)/B29 -> -0.11347375
A30: Tekort | B30: =1-B29 -> 0.3552559 | C30: =1-C29 -> 0.37042056 | D30: =1-D29 -> 0.36143181 | E30: =1-E29 -> 0.36753852 | F30: =1-F29 -> 0.36874201 | G30: =1-G29 -> 0.376457 | H30: =1-H29 -> 0.38475572 | I30: =1-I29 -> 0.39645339 | ... V30: =1-V29 -> 0.42841743
A32: Werknemers
A33: Populatie W1 | B33: ='Oplijsting (sub)categorieën KSZ'!C15 -> 3416845 | C33: ='Oplijsting (sub)categorieën KSZ'!D15 -> 3446922 | D33: ='Oplijsting (sub)categorieën KSZ'!E15 -> 3488326 | E33: ='Oplijsting (sub)categorieën KSZ'!F15 -> 3552305 | F33: ='Oplijsting (sub)categorieën KSZ'!G15 -> 3632158 | G33: ='Oplijsting (sub)categorieën KSZ'!H15 -> 3664695 | H33: ='Oplijsting (sub)categorieën KSZ'!I15 -> 3650975 | I33: ='Oplijsting (sub)categorieën KSZ'!J15 -> 3702275 | ... V33: ='Oplijsting (sub)categorieën KSZ'!W15 -> 3992877
A34: Populatie W2 | B34: ='Oplijsting (sub)categorieën KSZ'!C16 -> 3431288 | C34: ='Oplijsting (sub)categorieën KSZ'!D16 -> 3460962 | D34: ='Oplijsting (sub)categorieën KSZ'!E16 -> 3501575 | E34: ='Oplijsting (sub)categorieën KSZ'!F16 -> 3566422 | F34: ='Oplijsting (sub)categorieën KSZ'!G16 -> 3646646 | G34: ='Oplijsting (sub)categorieën KSZ'!H16 -> 3679558 | H34: ='Oplijsting (sub)categorieën KSZ'!I16 -> 3665867 | I34: ='Oplijsting (sub)categorieën KSZ'!J16 -> 3717768 | ... V34: ='Oplijsting (sub)categorieën KSZ'!W16 -> 4015175
A35: Bijdragen | B35: 32469268 | C35: 33123849 | D35: 34202276 | E35: 35153662 | F35: 37103312 | G35: 38476949 | H35: 39261165 | I35: 39580644 | J35: 41462766 | K35: 43343819 | L35: 44275103 | M35: 45842493 | N35: 47640683 | O35: 47640622 | P35: 48995748 | Q35: 49961681 | R35: 51749904 | S35: 50773064 | T35: 53722777 | U35: 58532826 | V35: 62867872 | W35: 65768583 | X35: 68200926
A36: Uitgaven | B36: 45740072 | C36: 49471194 | D36: 51489775 | E36: 53137695 | F36: 55551744 | G36: 55597965 | H36: 60005317 | I36: 62498799 | J36: 65753434 | K36: 67089304 | L36: 69743795 | M36: 73219534 | N36: 63212126 | O36: 65299033 | P36: 68913399 | Q36: 70920704 | R36: 73329307 | S36: 81169680 | T36: 81725543 | U36: 86385196 | V36: 93354528 | W36: 99309274 | X36: 1.0542195e+08
A37: Gecorrigeerd voor inflatie
A38: Bijdragen | B38: =B35*B4 -> 52656662 | C38: =C35*C4 -> 52857872 | D38: =D35*D4 -> 53420278 | E38: =E35*E4 -> 53952255 | F38: =F35*F4 -> 55955828 | G38: =G35*G4 -> 55676168 | H38: =H35*H4 -> 56478392 | I38: =I35*I4 -> 56001286 | ... V38: =V35*V4 -> 64934056
A39: Uitgaven | B39: =B36*B4 -> 74178434 | C39: =C36*C4 -> 78944391 | D39: =D36*D4 -> 80421492 | E39: =E36*E4 -> 81553337 | F39: =F36*F4 -> 83778069 | G39: =G36*G4 -> 80450288 | H39: =H36*H4 -> 86319491 | I39: =I36*I4 -> 88427392 | ... V39: =V36*V4 -> 96422672
A40: Per capita gecorrigeerd voor inflatie W1
A41: Bijdragen | B41: =B38/B$33 -> 15.410901 | C41: =C38/C$33 -> 15.334804 | D41: =D38/D$33 -> 15.314015 | E41: =E38/E$33 -> 15.187957 | F41: =F38/F$33 -> 15.40567 | G41: =G38/G$33 -> 15.192579 | H41: =H38/H$33 -> 15.4694 | I41: =I38/I$33 -> 15.126182 | ... V41: =V38/V$33 -> 16.262473
...

Sheet Bijdragen WN's & WG's opgesplit
A1: Opsplitsing WN's en WG's bijdragen + vergelijking totaal NB - totaal FOD SZ | B1: 2003 | C1: 2004 | D1: 2005 | E1: 2006 | F1: 2007 | G1: 2008 | H1: 2009 | I1: 2010 | J1: 2011 | K1: 2012 | L1: 2013 | M1: 2014 | N1: 2015 | O1: 2016 | P1: 2017 | Q1: 2018 | R1: 2019 | S1: 2020 | T1: 2021 | U1: 2022 | V1: 2023
A2: NBB: D.613: Werknemersbijdragen: Werkelijke sociale premies t.l.v. de werknemers | B2: =[1]Table!D47 -> 12106600 | C2: =[1]Table!E47 -> 12506700 | D2: =[1]Table!F47 -> 12709200 | E2: =[1]Table!G47 -> 13016500 | F2: =[1]Table!H47 -> 13848300 | G2: =[1]Table!I47 -> 14406900 | H2: =[1]Table!J47 -> 14645900 | I2: =[1]Table!K47 -> 14996600 | ... V2: =[1]Table!X47 -> 23772000
A3: NBB: Werkelijke sociale premies t.l.v. de werkgevers (D.611) | B3: =[1]Table!D38 -> 23708600 | C3: =[1]Table!E38 -> 24414200 | D3: =[1]Table!F38 -> 25251400 | E3: =[1]Table!G38 -> 26446900 | F3: =[1]Table!H38 -> 28215900 | G3: =[1]Table!I38 -> 29803000 | H3: =[1]Table!J38 -> 30354800 | I3: =[1]Table!K38 -> 31041200 | ... V3: =[1]Table!X38 -> 46011600
A4: Totaal bijdragen o.b.v. NBB | B4: =B2+B3 -> 35815200 | C4: =C2+C3 -> 36920900 | D4: =D2+D3 -> 37960600 | E4: =E2+E3 -> 39463400 | F4: =F2+F3 -> 42064200 | G4: =G2+G3 -> 44209900 | H4: =H2+H3 -> 45000700 | I4: =I2+I3 -> 46037800 | ... V4: =V2+V3 -> 69783600
A5: Totale gewone bijdragen o.b.v. data FOD SZ: "A. Werknemers_2000-2025" | B5: ='[2]Werknemers - Salariés'!D17 -> 29433700 | C5: ='[2]Werknemers - Salariés'!E17 -> 30644264 | D5: ='[2]Werknemers - Salariés'!F17 -> 32369813 | E5: ='[2]Werknemers - Salariés'!G17 -> 32469268 | F5: ='[2]Werknemers - Salariés'!H17 -> 33123849 | G5: ='[2]Werknemers - Salariés'!I17 -> 34202276 | H5: ='[2]Werknemers - Salariés'!J17 -> 35153662 | I5: ='[2]Werknemers - Salariés'!K17 -> 37103312 | ... V5: ='[2]Werknemers - Salariés'!X17 -> 50773064
A6: Verschil (%) (Nationale bank - FOD SZ) | B6: =(B4-B5)/B4 -> 0.17817855 | C6: =(C4-C5)/C4 -> 0.17000224 | D6: =(D4-D5)/D4 -> 0.14727867 | E6: =(E4-E5)/E4 -> 0.17723084 | F6: =(F4-F5)/F4 -> 0.21254063 | G6: =(G4-G5)/G4 -> 0.22636612 | H6: =(H4-H5)/H4 -> 0.21881966 | I6: =(I4-I5)/I4 -> 0.19406852 | ... V6: =(V4-V5)/V4 -> 0.27242126
A8: Aandeel WN | B8: =B2/B4 -> 0.33802966 | C8: =C2/C4 -> 0.3387431 | D8: =D2/D4 -> 0.33479977 | E8: =E2/E4 -> 0.32983727 | F8: =F2/F4 -> 0.3292182 | G8: =G2/G4 -> 0.32587497 | H8: =H2/H4 -> 0.32545938 | I8: =I2/I4 -> 0.32574537 | ... V8: =V2/V4 -> 0.3406531
A9: Aandeel WG | B9: =B3/B4 -> 0.66197034 | C9: =C3/C4 -> 0.6612569 | D9: =D3/D4 -> 0.66520023 | E9: =E3/E4 -> 0.67016273 | F9: =F3/F4 -> 0.6707818 | G9: =G3/G4 -> 0.67412503 | H9: =H3/H4 -> 0.67454062 | I9: =I3/I4 -> 0.67425463 | ... V9: =V3/V4 -> 0.6593469

Sheet Oplijsting (sub)categorieën KSZ
A1: Socio-economische positie | B1: Overeenstemmende nomenclatuurcodes | C1: 2003/4 | D1: 2004/4 | E1: 2005/4 | F1: 2006/4 | G1: 2007/4 | H1: 2008/4 | I1: 2009/4 | J1: 2010/4 | K1: 2011/4 | L1: 2012/4 | M1: 2013/4 | N1: 2014/4 | O1: 2015/4 | P1: 2016/4 | Q1: 2017/4 | R1: 2018/4 | S1: 2019/4 | T1: 2020/4 | U1: 2021/4 | V1: 2022/4 | W1: 2023/4 | X1: 2024/4
A2: Loontrekkende | B2: n11* (n111: in één job, n112: in meerdere jobs) | C2: 3282810 | D2: 3307868 | E2: 3343796 | F2: 3400589 | G2: 3469911 | H2: 3494375 | I2: 3476291 | J2: 3519456 | K2: 3534952 | L2: 3521105 | M2: 3504422 | N2: 3521770 | O2: 3543376 | P2: 3584978 | Q2: 3631146 | R2: 3677621 | S2: 3719648 | T2: 3685781 | U2: 3741208 | V2: 3781366 | W2: 3696753
A3: zelfstandige | B3: n12* (n121: in hoofdberoep, n122: in bijberoep, n123: na pensioenleeftijd) | C3: 607586 | D3: 610856 | E3: 619161 | F3: 628879 | G3: 644711 | H3: 658933 | I3: 671678 | J3: 684305 | K3: 696052 | L3: 710144 | M3: 719354 | N3: 730291 | O3: 746190 | P3: 762006 | Q3: 781334 | R3: 797011 | S3: 817839 | T3: 845105 | U3: 874522 | V3: 890990 | W3: 881138
A4: helper | B4: n13* (n131: in hoofdberoep, n132: in bijberoep, n133: na pensioenleeftijd) | C4: 97093 | D4: 92569 | E4: 86632 | F4: 82724 | G4: 79834 | H4: 76299 | I4: 69306 | J4: 66188 | K4: 64205 | L4: 62184 | M4: 60330 | N4: 58925 | O4: 58149 | P4: 56592 | Q4: 55022 | R4: 53891 | S4: 52358 | T4: 51145 | U4: 49780 | V4: 47354 | W4: 41763
A5: loontrekkend en zelfstandige/helper - voornaamste job loontrekkend | B5: n141 | C5: 134035 | D5: 139054 | E5: 144530 | F5: 151716 | G5: 162247 | H5: 170320 | I5: 174684 | J5: 182819 | K5: 189460 | L5: 196121 | M5: 200494 | N5: 205167 | O5: 209298 | P5: 216381 | Q5: 226925 | R5: 236408 | S5: 247270 | T5: 260911 | U5: 277876 | V5: 288473 | W5: 296124
A6: loontrekkend en zelfstandige/helper - voornaamste job zelfstandige | B6: n142 | C6: 12693 | D6: 12493 | E6: 11939 | F6: 12905 | G6: 13229 | H6: 13566 | I6: 13780 | J6: 14337 | K6: 14867 | L6: 14848 | M6: 15212 | N6: 15320 | O6: 16002 | P6: 16452 | Q6: 17236 | R6: 18001 | S6: 18790 | T6: 19065 | U6: 20364 | V6: 21284 | W6: 21344
A7: loontrekkend en zelfstandige/helper - voornaamste job helper | B7: n143 | C7: 1750 | D7: 1547 | E7: 1310 | F7: 1212 | G7: 1259 | H7: 1297 | I7: 1112 | J7: 1156 | K7: 1168 | L7: 1057 | M7: 1025 | N7: 1001 | O7: 1002 | P7: 1038 | Q7: 1050 | R7: 1019 | S7: 1017 | T7: 1001 | U7: 995 | V7: 1033 | W7: 954
A8: Totaal | C8: 4135967 | D8: 4164387 | E8: 4207368 | F8: 4278025 | G8: 4371191 | H8: 4414790 | I8: 4406851 | J8: 4468261 | K8: 4500704 | L8: 4505459 | M8: 4500837 | N8: 4532474 | O8: 4574017 | P8: 4637447 | Q8: 4712713 | R8: 4783951 | S8: 4856922 | T8: 4863008 | U8: 4964745 | V8: 5030500 | W8: 4938076
A9: NIEUW voorgestelde aangepaste totale populatie aangesloten zelfstandigen | B9: n12 + n13 + n142 + n143 | C9: =C3+C4+C6+C7 -> 719122 | D9: =D3+D4+D6+D7 -> 717465 | E9: =E3+E4+E6+E7 -> 719042 | F9: =F3+F4+F6+F7 -> 725720 | G9: =G3+G4+G6+G7 -> 739033 | H9: =H3+H4+H6+H7 -> 750095 | I9: =I3+I4+I6+I7 -> 755876 | J9: =J3+J4+J6+J7 -> 765986 | ... W9: =W3+W4+W6+W7 -> 945199
A10: NIEUW voorgestelde aangepaste totale populatie loontrekkenden | B10: n11 + n141 | C10: =C2+C5 -> 3416845 | D10: =D2+D5 -> 3446922 | E10: =E2+E5 -> 3488326 | F10: =F2+F5 -> 3552305 | G10: =G2+G5 -> 3632158 | H10: =H2+H5 -> 3664695 | I10: =I2+I5 -> 3650975 | J10: =J2+J5 -> 3702275 | ... W10: =W2+W5 -> 3992877
A11: *Noot: Je kan de cijfergegevens voor n111, n112, n121, n122, n123, n131, n132, en n133 niet afzonderlijk opvragen, laagst opvraagbare niveau hier is n11, n12, n13 | C11: =C9+C10 -> 4135967
A12: Extra: Zelfstandigen die "werkend als pensioentrekkende: Ja" aangevinkt hebben. Deze groep is een deel van totaalcijfer zelfstandigen n12, maar het is niet geheel duidelijk of dit perfect overlapt met n123: zelfstandige na pensioenleeftijd. | C12: 58 759 | D12: 60 441 | E12: 61 507 | F12: 62 585 | G12: 64 277 | H12: 65 985 | I12: 68 787 | J12: 71 861 | K12: 75 337 | L12: 80 298 | M12: 85 883 | N12: 90 814 | O12: 94 833 | P12: 99 772 | Q12: 105 445 | R12: 109 176 | S12: 114 964 | T12: 120 848 | U12: 126 882 | V12: 133 856 | W12: 140 286
